Workbook

Sheet 대시보드
B2: ="린매스업 매크로 대시보드" -> 린매스업 매크로 대시보드
B3: ="입력은 '매크로 계산기' 시트에서 하고, 이 시트는 결과와 가이드를 한눈에 보기 쉽게 정리한 화면입니다." -> 입력은 '매크로 계산기' 시트에서 하고, 이 시트는 결과와 가이드를 한눈에 보기 쉽게 정리한 화면입니다.
B5: ="오늘 목표 칼로리" -> 오늘 목표 칼로리 | F5: ="일일 총 소비량" -> 일일 총 소비량 | J5: ="자동 활동 판정" -> 자동 활동 판정
B6: =IF('매크로 계산기'!D27="","-",ROUND('매크로 계산기'!D27,0)&" kcal") -> 2439 kcal | F6: =IF('매크로 계산기'!B22="","-",ROUND('매크로 계산기'!B22,0)&" kcal") -> 2289 kcal | J6: =IF('매크로 계산기'!K35="","-",'매크로 계산기'!K35&CHAR(10)&"추천 계수 "&TEXT('매크로 계산기'!M35,"0.000")) -> 활동형 추천 계수 1.193
B9: ="매크로 요약" -> 매크로 요약 | J9: ="핵심 안내" -> 핵심 안내
B10: ="탄수화물" -> 탄수화물 | C10: =ROUND('매크로 계산기'!D28,0)&" g" -> 333 g | D10: =ROUND('매크로 계산기'!D28*4,0)&" kcal" -> 1332 kcal | E10: =IFERROR(ROUND(('매크로 계산기'!D28*4)/'매크로 계산기'!D27*100,0)&"%","-") -> 55% | J10: =IF('매크로 계산기'!M43="","2주 자동 보정을 쓰려면 이전 7일 평균체중과 최근 7일 평균체중을 입력하세요.","현재 자동 보정 제안: "&IF('매크로 계산기'!M43>0,"+","")&'매크로 계산기'!M43&" kcal/day") -> 현재 자동 보정 제안: -100 kcal/day
B11: ="단백질" -> 단백질 | C11: =ROUND('매크로 계산기'!D29,0)&" g" -> 143 g | D11: =ROUND('매크로 계산기'!D29*4,0)&" kcal" -> 570 kcal | E11: =IFERROR(ROUND(('매크로 계산기'!D29*4)/'매크로 계산기'!D27*100,0)&"%","-") -> 23% | J11: =IF('매크로 계산기'!K35="","활동 가이드 입력값을 채우면 추천 활동수준이 표시됩니다.","자동 활동 판정은 웨이트 빈도, 작업세트, 유산소 빈도, 걸음 수를 바탕으로 계산됩니다.") -> 자동 활동 판정은 웨이트 빈도, 작업세트, 유산소 빈도, 걸음 수를 바탕으로 계산됩니다.
B12: ="지방" -> 지방 | C12: =ROUND('매크로 계산기'!D30,0)&" g" -> 60 g | D12: =ROUND('매크로 계산기'!D30*9,0)&" kcal" -> 537 kcal | E12: =IFERROR(ROUND(('매크로 계산기'!D30*9)/'매크로 계산기'!D27*100,0)&"%","-") -> 22%
B13: ="요약 문장" -> 요약 문장 | C13: ="탄 "&ROUND('매크로 계산기'!D28,0)&"g / 단 "&ROUND('매크로 계산기'!D29,0)&"g / 지 "&ROUND('매크로 계산기'!D30,0)&"g" -> 탄 333g / 단 143g / 지 60g | J13: ="입력 위치: 매크로 계산기 시트" -> 입력 위치: 매크로 계산기 시트
B16: ="칼로리 구성" -> 칼로리 구성 | J16: ="현재 입력 요약" -> 현재 입력 요약
B17: ="기본 소비량" -> 기본 소비량 | C17: =ROUND('매크로 계산기'!B20,0)&" kcal" -> 2053 kcal | D17: ="운동 소모량" -> 운동 소모량 | E17: =ROUND('매크로 계산기'!B21,0)&" kcal" -> 236 kcal | F17: ="목적별 가감" -> 목적별 가감 | G17: =IFERROR(IF(VLOOKUP('매크로 계산기'!B13,기준데이터!$D$27:$E$29,2,FALSE())>0,"+"&ROUND(VLOOKUP('매크로 계산기'!B13,기준데이터!$D$27:$E$29,2,FALSE()),0),ROUND(VLOOKUP('매크로 계산기'!B13,기준데이터!$D$27:$E$29,2,FALSE()),0))&" kcal","-") -> +150 kcal | J17: ="체중 / 체지방" -> 체중 / 체지방 | K17: ='매크로 계산기'!B6&" kg / "&'매크로 계산기'!B7&"%" -> 75 kg / 35%
B18: ="공식 요약" -> 공식 요약 | C18: ="일일 총 소비량 = 기본 소비량 + 운동 소모량 / 최종 목표 = 일일 총 소비량 + 목적별 가감" -> 일일 총 소비량 = 기본 소비량 + 운동 소모량 / 최종 목표 = 일일 총 소비량 + 목적별 가감 | J18: ="활동수준 / 목표" -> 활동수준 / 목표 | K18: ='매크로 계산기'!B11&" / "&'매크로 계산기'!B13 -> 운동인 / 린매스업
J19: ="루틴 / 웨이트 시간" -> 루틴 / 웨이트 시간 | K19: ='매크로 계산기'!B12&" / "&'매크로 계산기'!I10&"분" -> REST / 60분
J20: ="유산소 시간" -> 유산소 시간 | K20: =IF('매크로 계산기'!B8="","-",'매크로 계산기'!B8&"분") -> 15분
B22: ="입력은 '매크로 계산기'에서, 해석은 '대시보드'에서 보는 구조로 분리했습니다." -> 입력은 '매크로 계산기'에서, 해석은 '대시보드'에서 보는 구조로 분리했습니다.

Sheet 매크로 계산기
A1: 🏃 런매스업 v2 — 신체정보 연동 매크로 보간 엔진 | H1: 🏃‍♂️ 유산소 운동 칼로리 계산기 (ACSM 공식 기반)
A2: 신체정보 · 강도값을 입력하면 오늘의 최적 매크로가 자동 계산됩니다 | H2: 속도 · 인클라인 · 시간을 입력하면 소비 칼로리와 유산소 강도가 자동 계산됩니다
A4: 👤 신체정보 입력 | C4: 📊 자동 계산값 | H4: ▶ 운동 입력
A5: 키 (cm) | B5: 173 | C5: 제지방체중 (LBM) | D5: =IFERROR(B6-(B6*B8/100),"") -> 63.75 | E5: kg | H5: 운동 종류 | I5: 트레드밀 워킹 | J5: 드롭다운 선택
A6: 체중 (kg) | B6: 75 | C6: BMR | D6: =IF(B11="일반인", IF(B10="남성", (10*B6+6.25*B5-5*B9+5)* IF(B8<=8, 1.028+(8-B8)/400, IF(B8<=35, 1+(15-B8)/250, 0.92-(B8-35)/180 ) ), (10*B6+6.25*B5-5*B9-161)* IF(B8<=18, 1.028+(18-B8)/400, IF(B8<=35, 1+(25-B8)/250, 0.96-(B8-35)/180 ) ) ), 370+(21.6*D5) ) -> 1747 | E6: kcal | F6: Katch-McArdle/Mifflin | H6: 속도 (km/h) | I6: 5 | J6: 트레드밀 표시 속도
A7: 골격근량 (kg) | B7: 35 | C7: 골격근 비율 | D7: =IFERROR(B7/B6,"") -> 0.46666667 | E7: % | H7: 인클라인 경사도 (%) | I7: 8 | J7: 0 ~ 15%
A8: 체지방률 (%) | B8: 15 | C8: 체지방량 | D8: =IFERROR(B6*B8/100,"") -> 11.25 | E8: kg | H8: 운동 시간 (분) | I8: 0 | J8: 분 단위 입력
A9: 만 나이 (세) | B9: 32 | C9: 업무 강도 (Y, 자동) | D9: =IFERROR(MAX(0,MIN(1,VLOOKUP(B14,기준데이터!$H$32:$I$36,2,FALSE())+B15)),"") -> 0 | E9: 업무유형 + 보정값 | H9: 체중 (kg) | I9: ='매크로 계산기'!B6 -> 75 | J9: 신체정보 자동 연동
A10: 성별 | B10: 남성 | C10: 유산소 강도 (Xc) | D10: =I23 -> 0.40079365 | E10: 유산소 계산기 연동 | H10: ="웨이트 시간 (분)" -> 웨이트 시간 (분) | I10: 60 | J10: ="실운동 시간 입력" -> 실운동 시간 입력
A11: 활동수준 | B11: 운동인 | C11: 활동계수 | D11: =IFERROR(VLOOKUP(B11,기준데이터!$D$12:$E$14,2,FALSE())+(D9*0.05),"") -> 1.175 | E11: ="생활활동 + 업무강도 소폭보정" -> 생활활동 + 업무강도 소폭보정
A12: 운동 루틴 | B12: REST | C12: 웨이트 강도 (Xw) | D12: =N44 -> 0 | E12: 운동 루틴 연동
A13: 목적 (프로그램) | B13: 린매스업 | C13: 통합 훈련강도 X | D13: =MIN(1,D12+D10*0.3) -> 0.1202381
A14: 업무 유형 | B14: 사무직 | C14: ="칼로리 가감" -> 칼로리 가감 | D14: =IFERROR(VLOOKUP(B13,기준데이터!$D$27:$G$29,2,FALSE()),1) -> 150 | E14: ="kcal" -> kcal
A15: 업무 보정 | B15: 0 | C15: -0.20 ~ +0.20 | D15: 업무유형 기본값에 개인차만 소폭 보정
A17: 🔥 대사량 계산 (TDEE) | H17: ⚙️ ACSM 공식 계산 과정
A18: 기초대사량 (BMR) | B18: =IFERROR(D6,"") -> 1747 | C18: kcal | H18: 속도 변환 (m/min) | I18: =(I6*1000/60) -> 83.333333 | J18: m/min
A19: ="생활계수 (NEAT)" -> 생활계수 (NEAT) | B19: =IFERROR(D11,"") -> 1.175 | C19: × | H19: VO2 (ACSM 공식) | I19: =IFERROR(IF(I5="트레드밀 워킹",(I6*1000/60)*0.1+(I6*1000/60)*(I7/100)*1.8+3.5,IF(I5="실외 러닝",(I6*1000/60)*0.2+3.5,(I6*1000/60)*0.2+(I6*1000/60)*(I7/100)*0.9+3.5)),"입력확인") -> 23.833333 | J19: ml/kg/min
A20: ="기본 소비량 (BMR×생활계수)" -> 기본 소비량 (BMR×생활계수) | B20: =IFERROR(D6*D11,"") -> 2052.725 | C20: kcal | H20: MET 추정값 | I20: =IFERROR(I19/3.5,"") -> 6.8095238 | J20: METs
A21: ="운동 소모량 (웨이트+유산소+EPOC)" -> 운동 소모량 (웨이트+유산소+EPOC) | B21: =IFERROR(O24+I22+I24,0) -> 236.25 | C21: kcal | H21: 소비 칼로리/분 | I21: =IFERROR((I19*I9)/1000*5,"") -> 8.9375
A22: ="일일 총 소비량 (기본+운동)" -> 일일 총 소비량 (기본+운동) | B22: =IFERROR(D6*D11+B21,"") -> 2288.975 | C22: kcal | H22: 유산소 소비 칼로리 (총) | I22: =IFERROR(I21*I8,"") -> 0
H23: 유산소 강도 (0~1) | I23: =IFERROR(MIN(1,MAX(0,(I20-2)/12)),"") -> 0.40079365
H24: EPOC (고강도 추가소비) | I24: =IFERROR(MAX(0,(I20-6)/9*I22*VLOOKUP(B13,기준데이터!$D$27:$G$29,4,FALSE())),0) -> 0 | J24: kcal | N24: ="helper_weight_kcal_O24" -> helper_weight_kcal_O24 | O24: =IFERROR((3+D12*4)*B6*3.5/200*IF(I10="",30,I10),0) -> 236.25
A25: 📊 오늘의 매크로 (최종 출력) | H25: 📋 결과 요약
A26: 항목 | B26: 보간 기준값 | C26: ="운동소모 참고 (O24+I22+I24)" -> 운동소모 참고 (O24+I22+I24) | D26: 최종값 | E26: 단위 | F26: 설명 | H26: 총 소비 칼로리 | I26: MET | J26: 유산소 강도 | K26: 운동 종류 | L26: 속도×경사도 | M26: 시간 | N26: helper_protein | O26: helper_fat | P26: helper_carb
A27: 칼로리 (kcal) | B27: =IFERROR(기준데이터!C3*(1-D13)*(1-D9)+기준데이터!C4*D13*(1-D9)+기준데이터!C5*(1-D13)*D9+기준데이터!C6*D13*D9,"") -> 2099.62 | C27: =IFERROR(O24+I22+I24,0) -> 236.25 | D27: =IFERROR(B22+VLOOKUP(B13,기준데이터!$D$27:$E$29,2,FALSE()),"") -> 2438.975 | E27: kcal | F27: ="일일 총소비(B22) + 목적별 가감" -> 일일 총소비(B22) + 목적별 가감 | H27: =IFERROR(I22,"") -> 0 | I27: =IFERROR(I20,"") -> 6.8095238 | J27: =IFERROR(I23,"") -> 0.40079365 | K27: =I5 -> 트레드밀 워킹 | L27: =IFERROR(I6&" km/h / "&I7&"%","") -> 5 km/h / 8% | M27: =IFERROR(I8&" 분","") -> 0 분 | N27: =IF(B13="다이어트",2.4,IF(B13="린매스업",2.2,2)) -> 2.2 | O27: =B6*(IF(B10="여성",0.7,0.6)+IF(B13="다이어트",0.1,0)+IF(D13>=0.85,0.05,0)) -> 45 | P27: =IF(B13="다이어트",IF(D13>=0.85,5,IF(D13>=0.5,4.5,4)),IF(B13="린매스업",IF(D13>=0.85,6,IF(D13>=0.5,5.5,5)),IF(D13>=0.85,7,IF(D13>=0.5,6.5,6))))+IF(D9>=1,0.5,IF(D9>=0.5,0.25,0))+IF(I20>=6,0.5,IF(I20>=4.5,0.25,0)) -> 5.5
A28: 탄수화물 (g) | B28: =IFERROR(기준데이터!D3*(1-D13)*(1-D9)+기준데이터!D4*D13*(1-D9)+기준데이터!D5*(1-D13)*D9+기준데이터!D6*D13*D9,"") -> 272.10721 | C28: =IFERROR((O24+I22+I24)*0.55/4,0) -> 32.484375 | D28: =IFERROR(MAX(0,MIN(P28,P29)),"") -> 333.10012 | E28: g | F28: 단백질·지방 하한 확보 후 남는 칼로리를 탄수로 배분 | N28: =IF(B13="다이어트",2,IF(B13="린매스업",1.8,1.6))+IF(B8<=IF(B10="남성",10,18),0.2,IF(B8<=IF(B10="남성",20,28),0.1,0))+IF(D13>=0.85,0.2,IF(D13>=0.5,0.1,0))+IF(B10="여성",0.1,0) -> 1.9 | O28: =D27*IF(B13="다이어트",0.2,IF(B13="린매스업",0.22,0.25))/9 -> 59.619389 | P28: =B6*P27 -> 412.5
A29: 단백질 (g) | B29: =IFERROR(VLOOKUP(B13,기준데이터!$D$27:$F$29,3,FALSE())*B6,"") -> 150 | C29: 0 | D29: =IFERROR(MIN(N31,N30),"") -> 142.5 | E29: g | F29: 체지방률·성별·훈련강도 반영 단백질 | H29: 📐 인클라인별 칼로리 배율 참고 (5km/h 워킹 기준, 체중 80kg, 30분) | N29: =MIN(N27,N28) -> 1.9 | O29: =IFERROR((D27-D29*4)*((B30*9)/(B28*4+B30*9))/9,0) -> 56.940794 | P29: =MAX(0,(D27-D29*4-O30*9)/4) -> 333.10012
A30: 지방 (g) | B30: =IFERROR(기준데이터!F3*(1-D13)*(1-D9)+기준데이터!F4*D13*(1-D9)+기준데이터!F5*(1-D13)*D9+기준데이터!F6*D13*D9,"") -> 45.687906 | C30: =IFERROR((O24+I22+I24)*0.25/9,0) -> 6.5625 | D30: =IFERROR(MAX(0,MIN(O31,(D27-D29*4-D28*4)/9)),"") -> 59.619389 | E30: g | F30: 지방 하한과 탄수 상한 적용 후 잔여 칼로리 | H30: 0% (평지) | I30: 3% (약경사) | J30: 5% (중경사) | K30: 8% (고경사) | L30: 10% (급경사) | M30: 15% (최대) | N30: =D27*IF(B13="다이어트",0.35,IF(B13="린매스업",0.3,0.28))/4 -> 182.92312 | O30: =MAX(O27,O28,O29) -> 59.619389
A31: 유산소 소비 (kcal) | B31: ─ | C31: =IFERROR(I22,0) -> 0 | D31: =IFERROR('매크로 계산기'!I22,0) -> 0 | E31: kcal | F31: 유산소 탭에서 계산 | H31: 142 kcal | I31: 196 kcal | J31: 232 kcal | K31: 286 kcal | L31: 322 kcal | M31: 412 kcal | N31: =B6*N29 -> 142.5 | O31: =MAX(0,(D27-D29*4)/9) -> 207.66389
A32: ="한눈에 보기" -> 한눈에 보기 | N32: ="항목" -> 항목 | O32: ="kcal" -> kcal | Q32: ="항목" -> 항목 | R32: ="kcal" -> kcal
A33: ="오늘 목표" -> 오늘 목표 | D33: ="총 소비" -> 총 소비 | H33: ="자동 활동 가이드" -> 자동 활동 가이드 | N33: ="탄수화물" -> 탄수화물 | O33: =MIN(1,MAX(0,(I34/5)*0.35+(K34/25)*0.25+(M34/4)*0.15+(I35/12000)*0.15+(D9*0.1))) -> 0.6225 | P33: ="일반형" -> 일반형 | Q33: ="탄수화물" -> 탄수화물 | R33: =D28*4 -> 1332.4005
A34: =IF(D27="","-",ROUND(D27,0)&" kcal") -> 2439 kcal | D34: =IF(B22="","-",ROUND(B22,0)&" kcal") -> 2289 kcal | H34: ="주당 웨이트 횟수" -> 주당 웨이트 횟수 | I34: =4 -> 4 | J34: ="세션당 작업세트" -> 세션당 작업세트 | K34: =18 -> 18 | L34: ="주당 유산소 횟수" -> 주당 유산소 횟수 | M34: =2 -> 2 | N34: ="단백질" -> 단백질 | O34: =1.1+O33*0.15 -> 1.193375 | P34: ="활동형" -> 활동형 | Q34: ="단백질" -> 단백질 | R34: =D29*4 -> 570
H35: ="하루 평균 걸음수" -> 하루 평균 걸음수 | I35: =7000 -> 7000 | J35: ="자동 판정" -> 자동 판정 | K35: =O35 -> 활동형 | L35: ="추천 생활계수" -> 추천 생활계수 | M35: =ROUND(O34,3) -> 1.193 | N35: ="지방" -> 지방 | O35: =IF(O34<1.14,P33,IF(O34<1.21,P34,P35)) -> 활동형 | P35: ="고활동형" -> 고활동형 | Q35: ="지방" -> 지방 | R35: =D30*9 -> 536.5745
A36: =IF(D27="","입력값을 채우면 핵심 결과가 자동 표시됩니다.","탄 " & ROUND(D28,0) & "g / 단 " & ROUND(D29,0) & "g / 지 " & ROUND(D30,0) & "g 기준으로 자동 계산된 결과입니다.") -> 탄 333g / 단 143g / 지 60g 기준으로 자동 계산된 결과입니다. | H36: ="활동 점수" -> 활동 점수 | I36: =ROUND(O33,2) -> 0.62 | J36: ="현재 활동수준" -> 현재 활동수준 | K36: =B11 -> 운동인 | L36: ="현재 기본계수" -> 현재 기본계수 | M36: =ROUND(O36,3) -> 1.175 | O36: =IFERROR(VLOOKUP(B11,기준데이터!$D$12:$E$14,2,FALSE()),"") -> 1.175 | P36: ="자동 가이드상 기본 활동계수를 조금 더 높게 보는 편이 적절합니다." -> 자동 가이드상 기본 활동계수를 조금 더 높게 보는 편이 적절합니다.
A37: ="매크로 요약" -> 매크로 요약 | D37: ="칼로리 구성" -> 칼로리 구성 | H37: ="가이드 메모" -> 가이드 메모 | I37: =O37&CHAR(10)&P39 -> 현재 선택한 활동수준이 자동 가이드와 대체로 잘 맞습니다. 웨이트 빈도, 작업세트, 유산소 빈도, 걸음수, 업무강도(Y)를 함께 반영한 자동 추천입니다. | N37: ="항목" -> 항목 | O37: =IF(O34-O36>0.02,P36,IF(O36-O34>0.02,P37,P38)) -> 현재 선택한 활동수준이 자동 가이드와 대체로 잘 맞습니다. | P37: ="자동 가이드상 기본 활동계수를 조금 더 낮게 보는 편이 적절합니다." -> 자동 가이드상 기본 활동계수를 조금 더 낮게 보는 편이 적절합니다. | Q37: ="항목" -> 항목 | R37: ="kcal" -> kcal
A38: ="탄수화물" -> 탄수화물 | B38: =ROUND(D28,0)&" g" -> 333 g | C38: =ROUND(D28*4,0)&" kcal" -> 1332 kcal | D38: ="기본소비" -> 기본소비 | E38: =ROUND(B20,0)&" kcal" -> 2053 kcal | N38: ="기본소비" -> 기본소비 | O38: =B20 -> 2052.725 | P38: ="현재 선택한 활동수준이 자동 가이드와 대체로 잘 맞습니다." -> 현재 선택한 활동수준이 자동 가이드와 대체로 잘 맞습니다. | Q38: ="기본소비" -> 기본소비 | R38: =B20 -> 2052.725
A39: ="단백질" -> 단백질 | B39: =ROUND(D29,0)&" g" -> 143 g | C39: =ROUND(D29*4,0)&" kcal" -> 570 kcal | D39: ="운동소모" -> 운동소모 | E39: =ROUND(B21,0)&" kcal" -> 236 kcal | N39: ="운동소모" -> 운동소모 | O39: =B21 -> 236.25 | P39: ="웨이트 빈도, 작업세트, 유산소 빈도, 걸음수, 업무강도(Y)를 함께 반영한 자동 추천입니다." -> 웨이트 빈도, 작업세트, 유산소 빈도, 걸음수, 업무강도(Y)를 함께 반영한 자동 추천입니다. | Q39: ="운동소모" -> 운동소모 | R39: =B21 -> 236.25
A40: ="지방" -> 지방 | B40: =ROUND(D30,0)&" g" -> 60 g | C40: =ROUND(D30*9,0)&" kcal" -> 537 kcal | D40: ="목표가감" -> 목표가감 | E40: =IFERROR(IF(VLOOKUP(B13,기준데이터!$D$27:$E$29,2,FALSE())>0,"+"&ROUND(VLOOKUP(B13,기준데이터!$D$27:$E$29,2,FALSE()),0),ROUND(VLOOKUP(B13,기준데이터!$D$27:$E$29,2,FALSE()),0))&" kcal","-") -> +150 kcal | N40: ="목표가감" -> 목표가감 | O40: =IFERROR(VLOOKUP(B13,기준데이터!$D$27:$E$29,2,FALSE()),0) -> 150 | P40: ="이전/최근 7일 평균체중을 입력하면 자동 보정이 활성화됩니다." -> 이전/최근 7일 평균체중을 입력하면 자동 보정이 활성화됩니다. | Q40: ="목표가감" -> 목표가감 | R40: =IFERROR(VLOOKUP(B13,기준데이터!$D$27:$E$29,2,FALSE()),0) -> 150
A41: ="열량 비중" -> 열량 비중 | B41: =ROUND((D28*4)/D27*100,0)&"% / "&ROUND((D29*4)/D27*100,0)&"% / "&ROUND((D30*9)/D27*100,0)&"%" -> 55% / 23% / 22% | D41: ="자동활동" -> 자동활동 | E41: =IF(K35="","-",K35&" / "&TEXT(M35,"0.000")) -> 활동형 / 1.193 | H41: ="2주 자동 보정" -> 2주 자동 보정 | P41: ="현재 칼로리 설정은 유지해도 무난해 보입니다." -> 현재 칼로리 설정은 유지해도 무난해 보입니다.
A42: =IF(K35="","자동 활동 가이드 입력값을 채우면 활동수준 추천이 표시됩니다.","자동 활동 판정: " & K35 & " / 추천 계수 " & TEXT(M35,"0.000")) -> 자동 활동 판정: 활동형 / 추천 계수 1.193 | H42: ="이전 7일 평균체중" -> 이전 7일 평균체중 | I42: 74.48 | J42: ="최근 7일 평균체중" -> 최근 7일 평균체중 | K42: 75.02 | L42: ="허리둘레 변화 (cm)" -> 허리둘레 변화 (cm) | M42: =0 -> 0 | O42: =IF(OR(I42="",K42=""),"",K42-I42) -> 0.54 | P42: ="현재 목표 기준으로 일일 " -> 현재 목표 기준으로 일일
...

Sheet 기준데이터
A1: 📋 기준데이터 — 신체정보 연동 동적 타입별 기준값
A2: 타입 | B2: 이름 | C2: 칼로리(kcal) | D2: 탄수화물(g) | E2: 단백질(g) | F2: 지방(g) | G2: X | H2: Y | I2: 비고
A3: C | B3: 완전회복 | C3: =IFERROR('매크로 계산기'!D6*'매크로 계산기'!D11*1,"") -> 2052.725 | D3: =IFERROR('매크로 계산기'!D6*'매크로 계산기'!D11*1*0.51/4,"") -> 261.72244 | E3: =150 -> 150 | F3: =IFERROR(('매크로 계산기'!D6*'매크로 계산기'!D11*1-'매크로 계산기'!D6*'매크로 계산기'!D11*1*0.51-150*4)/9,"") -> 45.092806 | G3: 0 | H3: 0 | I3: TDEE_base × 1.0
A4: B | B4: 표준린매스업 | C4: =IFERROR('매크로 계산기'!D6*'매크로 계산기'!D11*1.19,"") -> 2442.7427 | D4: =IFERROR('매크로 계산기'!D6*'매크로 계산기'!D11*1.19*0.57/4,"") -> 348.09084 | E4: =150 -> 150 | F4: =IFERROR(('매크로 계산기'!D6*'매크로 계산기'!D11*1.19-'매크로 계산기'!D6*'매크로 계산기'!D11*1.19*0.57-150*4)/9,"") -> 50.042154 | G4: 1 | H4: 0 | I4: TDEE_base × 1.19
A5: D | B5: 현장노동 | C5: =IFERROR('매크로 계산기'!D6*'매크로 계산기'!D11*1.09,"") -> 2237.4702 | D5: =IFERROR('매크로 계산기'!D6*'매크로 계산기'!D11*1.09*0.55/4,"") -> 307.65216 | E5: =150 -> 150 | F5: =IFERROR(('매크로 계산기'!D6*'매크로 계산기'!D11*1.09-'매크로 계산기'!D6*'매크로 계산기'!D11*1.09*0.55-150*4)/9,"") -> 45.206846 | G5: 0 | H5: 1 | I5: TDEE_base × 1.09
A6: A | B6: 극강도소모 | C6: =IFERROR('매크로 계산기'!D6*'매크로 계산기'!D11*1.28,"") -> 2627.488 | D6: =IFERROR('매크로 계산기'!D6*'매크로 계산기'!D11*1.28*0.58/4,"") -> 380.98576 | E6: =150 -> 150 | F6: =IFERROR(('매크로 계산기'!D6*'매크로 계산기'!D11*1.28-'매크로 계산기'!D6*'매크로 계산기'!D11*1.28*0.58-150*4)/9,"") -> 55.94944 | G6: 1 | H6: 1 | I6: TDEE_base × 1.28
A8: ="💡 TDEE_base = BMR ×" & TEXT('매크로 계산기'!D11,"0.000") & "(매크로 계산기 신체정보 자동 연동)" -> 💡 TDEE_base = BMR ×1.175(매크로 계산기 신체정보 자동 연동)
D10: 활동수준 연동 활동계수
D11: 활동수준 | E11: 활동계수
D12: 일반인 | E12: =1.1 -> 1.1
D13: 운동인 | E13: =1.175 -> 1.175
D14: 프로 | E14: =1.25 -> 1.25
A16: 📐 공식 설명
A17: =IF('매크로 계산기'!B11="일반인", "BMR(일반인)", "BMR(운동인/프로)") -> BMR(운동인/프로) | C17: =IF('매크로 계산기'!B11="일반인", "BMR = Mifflin-St Jeor 공식 적용 (키 반영)", "BMR = Katch-McArdle 공식 적용 (LBM 기반)") -> BMR = Katch-McArdle 공식 적용 (LBM 기반)
A18: 활동계수
A19: 통합 훈련강도
A20: 보간 방식
A21: ACSM 워킹 VO2
A22: ACSM 러닝 VO2
A23: kcal 환산
A24: 유산소 강도
D25: 🎯 목적별 계산 파라미터
D26: 목적 | E26: ="칼로리 가감(kcal)" -> 칼로리 가감(kcal) | F26: 단백질(g/kg) | G26: EPOC 계수
D27: 다이어트 | E27: =-400 -> -400 | F27: 2.2 | G27: 0.12
D28: 린매스업 | E28: =150 -> 150 | F28: 2 | G28: 0.07
D29: 벌크업 | E29: =400 -> 400 | F29: 1.8 | G29: 0
D30: ="칼로리 가감: 다이어트=-400 / 린매스업=+150 / 벌크업=+400 | EPOC: MET>6일 때만 활성화, 저강도 유산소는 자동 0" -> 칼로리 가감: 다이어트=-400 / 린매스업=+150 / 벌크업=+400 | EPOC: MET>6일 때만 활성화, 저강도 유산소는 자동 0
H31: 업무유형 | I31: 기본 Y
H32: 사무직 | I32: 0
H33: 혼합형 | I33: 0.25
H34: 활동형 | I34: 0.5
H35: 현장직 | I35: 0.75
H36: 고강도 현장 | I36: 1
H39: ="루틴" -> 루틴 | I39: ="웨이트강도(Xw)" -> 웨이트강도(Xw)
H40: ="REST" -> REST | I40: =0 -> 0
H41: ="PUSH" -> PUSH | I41: =0.8 -> 0.8
H42: ="UPPER" -> UPPER | I42: =0.8 -> 0.8
H43: ="PULL" -> PULL | I43: =0.85 -> 0.85
H44: ="LOWER" -> LOWER | I44: =0.85 -> 0.85
H45: ="LEGS" -> LEGS | I45: =1 -> 1
